<?xml version='1.0'?>

<robot name="my_bot" xmlns:xacro="http://www.ros.org/wiki/xacro">
  <xacro:include filename="$(find my_bot)/urdf/my_bot.gazebo" />


  <!-- chassis link footprint -->
  <link name="robot_footprint"></link>
  <joint name="robot_footprint_joint" type="fixed">
    <origin xyz="0 0 0" rpy="0 0 0" />
    <parent link="robot_footprint"/>
    <child link="chassis" />
  </joint>


  <!-- chassis link -->
  <link name='chassis'>
    <pose>0 0 0.15 0 0 0</pose>
    <inertial>
      <mass value="10.0"/>
      <origin xyz="0.0 0 0" rpy=" 0 0 0"/>
      <inertia
          ixx="0.1" ixy="0" ixz="0"
          iyy="0.1" iyz="0"
          izz="0.1"
      />
    </inertial>

    <collision name='chassis_collision'>
      <origin xyz="0 0 0" rpy=" 0 0 0"/>
      <geometry>
        <box size="0.4 0.2 0.05"/>
      </geometry>
    </collision>

    <visual name='chassis_visual'>
      <origin xyz="0 0 0" rpy=" 0 0 0"/>
      <geometry>
        <box size="0.4 0.2 0.05"/>
      </geometry>
      <material name="Red">
          <color rgba="1 0 0 3"/>
      </material> 
    </visual>


    <collision name='back_caster_collision'>
      <origin xyz="-0.15 0 -0.05" rpy=" 0 0 0"/>
      <geometry>
        <sphere radius="0.0499"/>
      </geometry>
    </collision>

    <visual name='back_caster_visual'>
      <origin xyz="-0.15 0 -0.05" rpy=" 0 0 0"/>
      <geometry>
        <sphere radius="0.05"/>
      </geometry>
    </visual>

    <collision name='front_caster_collision'>
      <origin xyz="0.15 0 -0.05" rpy=" 0 0 0"/>
      <geometry>
        <sphere radius="0.0499"/>
      </geometry>
    </collision>

    <visual name='front_caster_visual'>
      <origin xyz="0.15 0 -0.05" rpy=" 0 0 0"/>
      <geometry>
        <sphere radius="0.05"/>
      </geometry>
    </visual>

  </link>


  <!-- body -->
  <link name="body">
    <pose>0 0 0 0 0 0</pose>
    <inertial>
      <mass value="3.0"/>
      <origin xyz="0 0 0" rpy=" 0 0 0"/>
      <inertia
          ixx="0.1" ixy="0" ixz="0"
          iyy="0.1" iyz="0"
          izz="0.1"
      />
    </inertial>

    <collision name='body_collision'>
      <origin xyz="0 0 0" rpy=" 0 0 0"/>
      <geometry>
        <box size="0.3 0.18 0.2"/>
      </geometry>
    </collision>

    <visual name='body_visual'>
      <origin xyz="0 0 0" rpy=" 0 0 0"/>
      <geometry>
        <box size="0.3 0.18 0.2"/>
      </geometry>
      <material name="blue">
          <color rgba="0 0 1 3"/>
      </material> 
    </visual>
  </link>

  <joint type="fixed" name="body_joint">
    <origin xyz="0.04 0 0.125" rpy="0 0 0"/>
    <child link="body"/>
    <parent link="chassis"/>
  </joint>


  <!-- Two turbos -->
  <link name='left_turbo'>
    <inertial>
      <mass value="1.0"/>
      <origin xyz="0 0 0" rpy="0 0 0"/>
      <inertia
          ixx="0.1" ixy="0" ixz="0"
          iyy="0.1" iyz="0"
          izz="0.1"
      />
    </inertial>

    <collision name='left_turbo_collision'>
      <origin xyz="0 0 0" rpy="0 1.5707 0"/>
      <geometry>
        <cylinder radius="0.05" length="0.1"/>
      </geometry>
    </collision>

    <visual name='left_turbo_visual'>
      <origin xyz="0 0 0" rpy="0 1.5707 0"/>
      <geometry>
        <cylinder radius="0.05" length="0.1"/>
      </geometry>
      <material name="yellow">
          <color rgba="1 1 0 3"/>
      </material> 
    </visual>
  </link>

  <joint type="fixed" name="left_turbo_joint">
    <origin xyz="-0.18 -0.05 0" rpy="0 0 0"/>
    <child link="left_turbo"/>
    <parent link="body"/>
  </joint>

  <link name='right_turbo'>
    <inertial>
      <mass value="1.0"/>
      <origin xyz="0 0 0" rpy="0 0 0"/>
      <inertia
          ixx="0.1" ixy="0" ixz="0"
          iyy="0.1" iyz="0"
          izz="0.1"
      />
    </inertial>

    <collision name='right_turbo_collision'>
      <origin xyz="0 0 0" rpy="0 1.5707 0"/>
      <geometry>
        <cylinder radius="0.05" length="0.1"/>
      </geometry>
    </collision>

    <visual name='right_turbo_visual'>
      <origin xyz="0 0 0" rpy="0 1.5707 0"/>
      <geometry>
        <cylinder radius="0.05" length="0.1"/>
      </geometry>
      <material name="yellow"/>
    </visual>
  </link>

  <joint type="fixed" name="right_turbo_joint">
    <origin xyz="-0.18 0.05 0" rpy="0 0 0"/>
    <child link="right_turbo"/>
    <parent link="body"/>
  </joint>


  <!-- Neck -->
  <link name="neck">
    <pose>0 0 0.06 0 0 0</pose>
    <inertial>
      <mass value="0.3"/>
      <origin xyz="0 0 0" rpy="0 0 0"/>
      <inertia
          ixx="0.1" ixy="0" ixz="0"
          iyy="0.1" iyz="0"
          izz="0.1"
      />
    </inertial>

    <collision name='neck_collision'>
      <origin xyz="0 0 0" rpy="0 0 0"/>
      <geometry>
        <cylinder radius="0.015" length="0.12"/>
      </geometry>
    </collision>

    <visual name='neck_visual'>
      <origin xyz="0 0 0" rpy=" 0 0 0"/>
      <geometry>
        <cylinder radius="0.015" length="0.12"/>
      </geometry>
      <material name="pink">
          <color rgba="0.94 0.62 0.75 3"/>
      </material> 
    </visual>
  </link>

  <joint type="fixed" name="neck_joint">
    <origin xyz="0.12 0 0.1" rpy="0 0 0"/>
    <child link="neck"/>
    <parent link="body"/>
  </joint>

  <!-- camera_box -->
  <link name="camera_box">
    <pose>0 0 0.02 0 0 0</pose>
    <inertial>
      <mass value="0.3"/>
      <origin xyz="0 0 0" rpy=" 0 0 0"/>
      <inertia
          ixx="0.1" ixy="0" ixz="0"
          iyy="0.1" iyz="0"
          izz="0.1"
      />
    </inertial>
    <collision name='camera_box'>
      <origin xyz="0 0 0" rpy=" 0 0 0"/>
      <geometry>
       <box size="0.05 0.18 0.03"/>
      </geometry>  
    </collision>

    <visual name='camera_box'>
      <origin xyz="0 0 0" rpy=" 0 0 0"/>
      <geometry>
       <box size="0.05 0.18 0.03"/>
      </geometry>
      <material name="black">
          <color rgba="0 0 1 1"/>
      </material>  
    </visual>
  </link>

  <joint type="fixed" name="camera_box_joint">
    <origin xyz="0 0 0.06" rpy="0 0 0"/>
    <child link="camera_box"/>
    <parent link="neck"/>
  </joint>

  <!-- two wheels -->
  <link name='left_wheel'>
    <inertial>
      <mass value="3.0"/>
      <origin xyz="0 0 0" rpy="0 0 0"/>
      <inertia
          ixx="0.1" ixy="0" ixz="0"
          iyy="0.1" iyz="0"
          izz="0.1"
      />
    </inertial>

    <collision name='left_wheel_collision'>
      <origin xyz="0 0 0" rpy="0 1.5707 1.5707"/>
      <geometry>
        <cylinder radius="0.1" length="0.05"/>
      </geometry>
    </collision>

    <visual name='left_wheel_visual'>
      <origin xyz="0 0 0" rpy="0 1.5707 1.5707"/>
      <geometry>
        <cylinder radius="0.1" length="0.05"/>
      </geometry>
      <material name="green">
          <color rgba="0 1 0 3"/>
      </material> 
    </visual>

  </link>

  <joint type="continuous" name="left_wheel_hinge">
    <origin xyz="0 0.15 0" rpy="0 0 0"/>
    <child link="left_wheel"/>
    <parent link="chassis"/>
    <axis xyz="0 1 0" rpy="0 0 0"/>
    <limit effort="10000" velocity="1000"/>
    <dynamics damping="1.0" friction="1.0"/>
  </joint>

  <link name='right_wheel'>
    <inertial>
      <mass value="3.0"/>
      <origin xyz="0 0 0" rpy="0 0 0"/>
      <inertia
          ixx="0.1" ixy="0" ixz="0"
          iyy="0.1" iyz="0"
          izz="0.1"
      />
    </inertial>

    <collision name='right_wheel_collision'>
      <origin xyz="0 0 0" rpy="0 1.5707 1.5707"/>
      <geometry>
        <cylinder radius="0.1" length="0.05"/>
      </geometry>
    </collision>

    <visual name='right_wheel_visual'>
      <origin xyz="0 0 0" rpy="0 1.5707 1.5707"/>
      <geometry>
        <cylinder radius="0.1" length="0.05"/>
      </geometry>
      <material name="green"/>
    </visual>

  </link>

  <joint type="continuous" name="right_wheel_hinge">
    <origin xyz="0 -0.15 0" rpy="0 0 0"/>
    <child link="right_wheel"/>
    <parent link="chassis"/>
    <axis xyz="0 1 0" rpy="0 0 0"/>
    <limit effort="10000" velocity="1000"/>
    <dynamics damping="1.0" friction="1.0"/>
  </joint>


  <!-- camera -->
  <link name='camera'>
    <inertial>
      <mass value="0.1"/>
      <inertia
          ixx="1e-6" ixy="0" ixz="0"
          iyy="1e-6" iyz="0"
          izz="1e-6"
      />
    </inertial>

    <collision name='camera_collision'>
      <origin xyz="0 0 0" rpy="0 0 0"/>
      <geometry>
        <box size="0.01 0.13 0.015"/>
      </geometry>
    </collision>

    <visual name='camera_visual'>
      <origin xyz="0 0 0" rpy="0 0 0"/>
      <geometry>
        <box size="0.01 0.13 0.015"/>
      </geometry>
      <material name="yellow"/>
    </visual>
  </link>

  <joint type="fixed" name="camera_joint">
    <origin xyz="0.025 0 0" rpy="0 0 0"/>
    <child link="camera"/>
    <parent link="camera_box"/>
  </joint>


  <!-- hokuyo -->
  <link name='hokuyo'>
    <inertial>
      <mass value="0.1"/>
      <inertia
          ixx="1e-6" ixy="0" ixz="0"
          iyy="1e-6" iyz="0"
          izz="1e-6"
      />
    </inertial>

    <collision name='hokuyo_collision'>
      <origin xyz="0.0 0 0" rpy="0 0 0"/>
      <geometry>
        <box size="0.1 0.1 0.1"/>
      </geometry>
    </collision>

    <visual name='hokuyo_visual'>
      <origin xyz="0.0 0 0" rpy="0 0 0"/>
      <geometry>
        <mesh filename="package://my_bot/meshes/hokuyo.dae"/>
      </geometry>
      <material name="red"/>
    </visual>
  </link>

  <joint type="fixed" name="hokuyo_joint">
    <origin xyz="0 0 0.02" rpy="0 0 0"/>
    <child link="hokuyo"/>
    <parent link="camera_box"/>
  </joint>

</robot>
